[2020-01-02 09:41:16,347: INFO/MainProcess] beat: Starting...
[2020-01-04 01:52:07,043: INFO/MainProcess] beat: Starting...
[2020-01-04 03:23:12,031: INFO/MainProcess] beat: Starting...
<<<<<<< HEAD
[2020-01-04 03:35:35,931: INFO/MainProcess] beat: Starting...
[2020-01-04 04:00:00,126: ERROR/MainProcess] beat: Connection error: [Errno 111] Connection refused. Trying again in 2.0 seconds...
[2020-01-04 04:00:02,139: ERROR/MainProcess] beat: Connection error: [Errno 111] Connection refused. Trying again in 4.0 seconds...
[2020-01-04 04:00:06,158: ERROR/MainProcess] beat: Connection error: [Errno 111] Connection refused. Trying again in 6.0 seconds...
[2020-01-04 04:00:12,181: ERROR/MainProcess] beat: Connection error: [Errno 111] Connection refused. Trying again in 8.0 seconds...
[2020-01-04 04:00:20,199: ERROR/MainProcess] beat: Connection error: [Errno 111] Connection refused. Trying again in 10.0 seconds...
[2020-01-04 04:00:30,219: ERROR/MainProcess] beat: Connection error: [Errno 111] Connection refused. Trying again in 12.0 seconds...
[2020-01-04 04:00:42,242: ERROR/MainProcess] beat: Connection error: [Errno 111] Connection refused. Trying again in 14.0 seconds...
[2020-01-04 04:00:56,273: ERROR/MainProcess] beat: Connection error: [Errno 111] Connection refused. Trying again in 16.0 seconds...
[2020-01-04 04:01:12,306: ERROR/MainProcess] beat: Connection error: [Errno 111] Connection refused. Trying again in 18.0 seconds...
[2020-01-04 04:01:30,336: ERROR/MainProcess] beat: Connection error: [Errno 111] Connection refused. Trying again in 20.0 seconds...
[2020-01-04 04:01:52,610: ERROR/MainProcess] beat: Connection error: [Errno 111] Connection refused. Trying again in 22.0 seconds...
[2020-01-04 04:02:14,652: ERROR/MainProcess] beat: Connection error: [Errno 111] Connection refused. Trying again in 24.0 seconds...
[2020-01-04 04:02:38,692: ERROR/MainProcess] beat: Connection error: [Errno 111] Connection refused. Trying again in 26.0 seconds...
[2020-01-04 04:03:04,733: ERROR/MainProcess] beat: Connection error: [Errno 111] Connection refused. Trying again in 28.0 seconds...
[2020-01-04 04:03:32,779: ERROR/MainProcess] beat: Connection error: [Errno 111] Connection refused. Trying again in 30.0 seconds...
[2020-01-04 04:04:02,825: ERROR/MainProcess] beat: Connection error: [Errno 111] Connection refused. Trying again in 32.0 seconds...
[2020-01-04 04:04:34,865: ERROR/MainProcess] beat: Connection error: [Errno 111] Connection refused. Trying again in 32.0 seconds...
[2020-01-04 04:05:06,913: ERROR/MainProcess] beat: Connection error: [Errno 111] Connection refused. Trying again in 32.0 seconds...
[2020-01-04 04:05:38,960: ERROR/MainProcess] beat: Connection error: [Errno 111] Connection refused. Trying again in 32.0 seconds...
[2020-01-04 04:06:11,006: ERROR/MainProcess] beat: Connection error: [Errno 111] Connection refused. Trying again in 32.0 seconds...
[2020-01-04 04:06:43,048: ERROR/MainProcess] beat: Connection error: [Errno 111] Connection refused. Trying again in 32.0 seconds...
[2020-01-04 04:07:15,090: ERROR/MainProcess] beat: Connection error: [Errno 111] Connection refused. Trying again in 32.0 seconds...
[2020-01-04 04:07:47,139: ERROR/MainProcess] beat: Connection error: [Errno 111] Connection refused. Trying again in 32.0 seconds...
[2020-01-04 04:08:19,183: ERROR/MainProcess] beat: Connection error: [Errno 111] Connection refused. Trying again in 32.0 seconds...
[2020-01-04 04:08:51,226: ERROR/MainProcess] beat: Connection error: [Errno 111] Connection refused. Trying again in 32.0 seconds...
[2020-01-04 04:09:23,269: ERROR/MainProcess] beat: Connection error: [Errno 111] Connection refused. Trying again in 32.0 seconds...
[2020-01-04 04:09:55,317: ERROR/MainProcess] beat: Connection error: [Errno 111] Connection refused. Trying again in 32.0 seconds...
[2020-01-04 04:10:27,365: ERROR/MainProcess] beat: Connection error: [Errno 111] Connection refused. Trying again in 32.0 seconds...
[2020-01-04 04:10:59,408: ERROR/MainProcess] beat: Connection error: [Errno 111] Connection refused. Trying again in 32.0 seconds...
[2020-01-04 04:11:31,452: ERROR/MainProcess] beat: Connection error: [Errno 111] Connection refused. Trying again in 32.0 seconds...
[2020-01-04 04:12:03,497: ERROR/MainProcess] beat: Connection error: [Errno 111] Connection refused. Trying again in 32.0 seconds...
[2020-01-04 04:12:35,539: ERROR/MainProcess] beat: Connection error: [Errno 111] Connection refused. Trying again in 32.0 seconds...
[2020-01-04 04:13:07,585: ERROR/MainProcess] beat: Connection error: [Errno 111] Connection refused. Trying again in 32.0 seconds...
[2020-01-04 04:13:39,629: ERROR/MainProcess] beat: Connection error: [Errno 111] Connection refused. Trying again in 32.0 seconds...
[2020-01-04 04:14:11,679: ERROR/MainProcess] beat: Connection error: [Errno 111] Connection refused. Trying again in 32.0 seconds...
[2020-01-04 04:14:43,729: ERROR/MainProcess] beat: Connection error: [Errno 111] Connection refused. Trying again in 32.0 seconds...
[2020-01-04 04:15:15,779: ERROR/MainProcess] beat: Connection error: [Errno 111] Connection refused. Trying again in 32.0 seconds...
[2020-01-04 04:15:47,821: ERROR/MainProcess] beat: Connection error: [Errno 111] Connection refused. Trying again in 32.0 seconds...
[2020-01-04 04:16:19,872: ERROR/MainProcess] beat: Connection error: [Errno 111] Connection refused. Trying again in 32.0 seconds...
[2020-01-04 04:16:51,917: ERROR/MainProcess] beat: Connection error: [Errno 111] Connection refused. Trying again in 32.0 seconds...
[2020-01-04 04:17:23,962: ERROR/MainProcess] beat: Connection error: [Errno 111] Connection refused. Trying again in 32.0 seconds...
[2020-01-04 04:17:56,006: ERROR/MainProcess] beat: Connection error: [Errno 111] Connection refused. Trying again in 32.0 seconds...
[2020-01-04 04:18:28,055: ERROR/MainProcess] beat: Connection error: [Errno 111] Connection refused. Trying again in 32.0 seconds...
[2020-01-04 04:19:00,097: ERROR/MainProcess] beat: Connection error: [Errno 111] Connection refused. Trying again in 32.0 seconds...
[2020-01-04 04:19:32,145: ERROR/MainProcess] beat: Connection error: [Errno 111] Connection refused. Trying again in 32.0 seconds...
[2020-01-04 04:20:04,192: ERROR/MainProcess] beat: Connection error: [Errno 111] Connection refused. Trying again in 32.0 seconds...
[2020-01-04 04:20:36,239: ERROR/MainProcess] beat: Connection error: [Errno 111] Connection refused. Trying again in 32.0 seconds...
[2020-01-04 04:21:08,285: ERROR/MainProcess] beat: Connection error: [Errno 111] Connection refused. Trying again in 32.0 seconds...
[2020-01-04 04:21:40,335: ERROR/MainProcess] beat: Connection error: [Errno 111] Connection refused. Trying again in 32.0 seconds...
[2020-01-04 04:22:12,381: ERROR/MainProcess] beat: Connection error: [Errno 111] Connection refused. Trying again in 32.0 seconds...
[2020-01-04 04:22:44,426: ERROR/MainProcess] beat: Connection error: [Errno 111] Connection refused. Trying again in 32.0 seconds...
[2020-01-04 04:23:16,470: ERROR/MainProcess] beat: Connection error: [Errno 111] Connection refused. Trying again in 32.0 seconds...
[2020-01-04 04:23:48,515: ERROR/MainProcess] beat: Connection error: [Errno 111] Connection refused. Trying again in 32.0 seconds...
[2020-01-04 04:24:20,559: ERROR/MainProcess] beat: Connection error: [Errno 111] Connection refused. Trying again in 32.0 seconds...
[2020-01-04 04:24:52,607: ERROR/MainProcess] beat: Connection error: [Errno 111] Connection refused. Trying again in 32.0 seconds...
[2020-01-04 04:25:24,651: ERROR/MainProcess] beat: Connection error: [Errno 111] Connection refused. Trying again in 32.0 seconds...
[2020-01-04 04:25:56,696: ERROR/MainProcess] beat: Connection error: [Errno 111] Connection refused. Trying again in 32.0 seconds...
[2020-01-04 04:26:28,742: ERROR/MainProcess] beat: Connection error: [Errno 111] Connection refused. Trying again in 32.0 seconds...
[2020-01-04 04:27:00,787: ERROR/MainProcess] beat: Connection error: [Errno 111] Connection refused. Trying again in 32.0 seconds...
[2020-01-04 04:27:32,838: ERROR/MainProcess] beat: Connection error: [Errno 111] Connection refused. Trying again in 32.0 seconds...
[2020-01-04 04:28:04,883: ERROR/MainProcess] beat: Connection error: [Errno 111] Connection refused. Trying again in 32.0 seconds...
[2020-01-04 04:28:36,929: ERROR/MainProcess] beat: Connection error: [Errno 111] Connection refused. Trying again in 32.0 seconds...
[2020-01-04 04:29:08,977: ERROR/MainProcess] beat: Connection error: [Errno 111] Connection refused. Trying again in 32.0 seconds...
[2020-01-04 04:29:41,021: ERROR/MainProcess] beat: Connection error: [Errno 111] Connection refused. Trying again in 32.0 seconds...
[2020-01-04 04:30:13,066: ERROR/MainProcess] beat: Connection error: [Errno 111] Connection refused. Trying again in 32.0 seconds...
[2020-01-04 04:30:45,114: ERROR/MainProcess] beat: Connection error: [Errno 111] Connection refused. Trying again in 32.0 seconds...
[2020-01-04 04:31:17,161: ERROR/MainProcess] beat: Connection error: [Errno 111] Connection refused. Trying again in 32.0 seconds...
[2020-01-04 04:31:49,200: ERROR/MainProcess] beat: Connection error: [Errno 111] Connection refused. Trying again in 32.0 seconds...
[2020-01-04 04:32:21,239: ERROR/MainProcess] beat: Connection error: [Errno 111] Connection refused. Trying again in 32.0 seconds...
[2020-01-04 04:32:53,286: ERROR/MainProcess] beat: Connection error: [Errno 111] Connection refused. Trying again in 32.0 seconds...
[2020-01-04 04:33:25,331: ERROR/MainProcess] beat: Connection error: [Errno 111] Connection refused. Trying again in 32.0 seconds...
[2020-01-04 04:33:57,373: ERROR/MainProcess] beat: Connection error: [Errno 111] Connection refused. Trying again in 32.0 seconds...
[2020-01-04 04:34:29,416: ERROR/MainProcess] beat: Connection error: [Errno 111] Connection refused. Trying again in 32.0 seconds...
[2020-01-04 04:35:01,460: ERROR/MainProcess] beat: Connection error: [Errno 111] Connection refused. Trying again in 32.0 seconds...
[2020-01-04 04:35:33,511: ERROR/MainProcess] beat: Connection error: [Errno 111] Connection refused. Trying again in 32.0 seconds...
[2020-01-04 04:36:05,557: ERROR/MainProcess] beat: Connection error: [Errno 111] Connection refused. Trying again in 32.0 seconds...
[2020-01-04 04:36:37,607: ERROR/MainProcess] beat: Connection error: [Errno 111] Connection refused. Trying again in 32.0 seconds...
[2020-01-04 04:37:09,649: ERROR/MainProcess] beat: Connection error: [Errno 111] Connection refused. Trying again in 32.0 seconds...
[2020-01-04 04:37:41,697: ERROR/MainProcess] beat: Connection error: [Errno 111] Connection refused. Trying again in 32.0 seconds...
[2020-01-04 04:38:13,748: ERROR/MainProcess] beat: Connection error: [Errno 111] Connection refused. Trying again in 32.0 seconds...
[2020-01-04 04:38:45,789: ERROR/MainProcess] beat: Connection error: [Errno 111] Connection refused. Trying again in 32.0 seconds...
[2020-01-04 04:39:17,831: ERROR/MainProcess] beat: Connection error: [Errno 111] Connection refused. Trying again in 32.0 seconds...
[2020-01-04 04:39:49,881: ERROR/MainProcess] beat: Connection error: [Errno 111] Connection refused. Trying again in 32.0 seconds...
[2020-01-04 04:43:19,123: INFO/MainProcess] beat: Starting...
=======
[2020-01-04 04:31:36,091: INFO/MainProcess] beat: Starting...
[2020-01-04 04:33:50,645: INFO/MainProcess] beat: Starting...
[2020-01-04 04:50:35,382: INFO/MainProcess] beat: Starting...
[2020-01-04 04:55:34,194: INFO/MainProcess] beat: Starting...
[2020-01-04 04:56:57,033: INFO/MainProcess] beat: Starting...
>>>>>>> 243987882616714081153d14670801c803fc280f
[2020-01-05 13:43:03,254: INFO/MainProcess] beat: Starting...
[2020-01-05 13:52:10,544: INFO/MainProcess] beat: Starting...
[2020-01-07 03:54:58,378: INFO/MainProcess] beat: Starting...
[2020-01-07 04:00:00,021: ERROR/MainProcess] beat: Connection error: [Errno 111] Connection refused. Trying again in 2.0 seconds...
[2020-01-07 04:00:02,039: ERROR/MainProcess] beat: Connection error: [Errno 111] Connection refused. Trying again in 4.0 seconds...
[2020-01-07 04:00:06,057: ERROR/MainProcess] beat: Connection error: [Errno 111] Connection refused. Trying again in 6.0 seconds...
[2020-01-07 04:00:12,082: ERROR/MainProcess] beat: Connection error: [Errno 111] Connection refused. Trying again in 8.0 seconds...
[2020-01-07 04:00:20,106: ERROR/MainProcess] beat: Connection error: [Errno 111] Connection refused. Trying again in 10.0 seconds...
[2020-01-07 04:00:30,129: ERROR/MainProcess] beat: Connection error: [Errno 111] Connection refused. Trying again in 12.0 seconds...
[2020-01-07 04:00:42,157: ERROR/MainProcess] beat: Connection error: [Errno 111] Connection refused. Trying again in 14.0 seconds...
[2020-01-07 04:00:56,185: ERROR/MainProcess] beat: Connection error: [Errno 111] Connection refused. Trying again in 16.0 seconds...
[2020-01-07 04:01:12,218: ERROR/MainProcess] beat: Connection error: [Errno 111] Connection refused. Trying again in 18.0 seconds...
[2020-01-07 04:01:30,251: ERROR/MainProcess] beat: Connection error: [Errno 111] Connection refused. Trying again in 20.0 seconds...
[2020-01-07 04:01:50,286: ERROR/MainProcess] beat: Connection error: [Errno 111] Connection refused. Trying again in 22.0 seconds...
[2020-01-07 04:02:12,324: ERROR/MainProcess] beat: Connection error: [Errno 111] Connection refused. Trying again in 24.0 seconds...
[2020-01-07 04:02:36,363: ERROR/MainProcess] beat: Connection error: [Errno 111] Connection refused. Trying again in 26.0 seconds...
[2020-01-07 04:03:02,404: ERROR/MainProcess] beat: Connection error: [Errno 111] Connection refused. Trying again in 28.0 seconds...
[2020-01-07 04:03:30,448: ERROR/MainProcess] beat: Connection error: [Errno 111] Connection refused. Trying again in 30.0 seconds...
[2020-01-07 04:04:00,487: ERROR/MainProcess] beat: Connection error: [Errno 111] Connection refused. Trying again in 32.0 seconds...
[2020-01-07 04:04:32,531: ERROR/MainProcess] beat: Connection error: [Errno 111] Connection refused. Trying again in 32.0 seconds...
[2020-01-07 04:05:04,572: ERROR/MainProcess] beat: Connection error: [Errno 111] Connection refused. Trying again in 32.0 seconds...
[2020-01-07 04:05:36,618: ERROR/MainProcess] beat: Connection error: [Errno 111] Connection refused. Trying again in 32.0 seconds...
[2020-01-07 04:06:08,667: ERROR/MainProcess] beat: Connection error: [Errno 111] Connection refused. Trying again in 32.0 seconds...
[2020-01-07 04:06:40,718: ERROR/MainProcess] beat: Connection error: [Errno 111] Connection refused. Trying again in 32.0 seconds...
[2020-01-07 04:07:12,765: ERROR/MainProcess] beat: Connection error: [Errno 111] Connection refused. Trying again in 32.0 seconds...
[2020-01-07 04:07:44,815: ERROR/MainProcess] beat: Connection error: [Errno 111] Connection refused. Trying again in 32.0 seconds...
[2020-01-07 04:08:16,860: ERROR/MainProcess] beat: Connection error: [Errno 111] Connection refused. Trying again in 32.0 seconds...
[2020-01-07 04:08:48,910: ERROR/MainProcess] beat: Connection error: [Errno 111] Connection refused. Trying again in 32.0 seconds...
[2020-01-07 04:09:20,956: ERROR/MainProcess] beat: Connection error: [Errno 111] Connection refused. Trying again in 32.0 seconds...
[2020-01-07 04:09:53,003: ERROR/MainProcess] beat: Connection error: [Errno 111] Connection refused. Trying again in 32.0 seconds...
[2020-01-07 04:10:25,056: ERROR/MainProcess] beat: Connection error: [Errno 111] Connection refused. Trying again in 32.0 seconds...
[2020-01-07 04:10:57,107: ERROR/MainProcess] beat: Connection error: [Errno 111] Connection refused. Trying again in 32.0 seconds...
[2020-01-07 04:11:29,156: ERROR/MainProcess] beat: Connection error: [Errno 111] Connection refused. Trying again in 32.0 seconds...
[2020-01-07 04:12:01,201: ERROR/MainProcess] beat: Connection error: [Errno 111] Connection refused. Trying again in 32.0 seconds...
[2020-01-07 04:12:33,246: ERROR/MainProcess] beat: Connection error: [Errno 111] Connection refused. Trying again in 32.0 seconds...
[2020-01-07 04:13:05,298: ERROR/MainProcess] beat: Connection error: [Errno 111] Connection refused. Trying again in 32.0 seconds...
[2020-01-07 04:13:37,356: ERROR/MainProcess] beat: Connection error: [Errno 111] Connection refused. Trying again in 32.0 seconds...
[2020-01-07 04:14:09,403: ERROR/MainProcess] beat: Connection error: [Errno 111] Connection refused. Trying again in 32.0 seconds...
[2020-01-07 04:14:41,450: ERROR/MainProcess] beat: Connection error: [Errno 111] Connection refused. Trying again in 32.0 seconds...
[2020-01-07 04:15:13,500: ERROR/MainProcess] beat: Connection error: [Errno 111] Connection refused. Trying again in 32.0 seconds...
[2020-01-07 04:15:45,552: ERROR/MainProcess] beat: Connection error: [Errno 111] Connection refused. Trying again in 32.0 seconds...
[2020-01-07 04:16:17,606: ERROR/MainProcess] beat: Connection error: [Errno 111] Connection refused. Trying again in 32.0 seconds...
[2020-01-07 04:16:49,656: ERROR/MainProcess] beat: Connection error: [Errno 111] Connection refused. Trying again in 32.0 seconds...
[2020-01-07 04:17:21,703: ERROR/MainProcess] beat: Connection error: [Errno 111] Connection refused. Trying again in 32.0 seconds...
[2020-01-07 04:17:53,757: ERROR/MainProcess] beat: Connection error: [Errno 111] Connection refused. Trying again in 32.0 seconds...
[2020-01-07 04:18:25,804: ERROR/MainProcess] beat: Connection error: [Errno 111] Connection refused. Trying again in 32.0 seconds...
[2020-01-07 04:18:57,853: ERROR/MainProcess] beat: Connection error: [Errno 111] Connection refused. Trying again in 32.0 seconds...
[2020-01-07 04:19:29,900: ERROR/MainProcess] beat: Connection error: [Errno 111] Connection refused. Trying again in 32.0 seconds...
[2020-01-07 04:20:01,949: ERROR/MainProcess] beat: Connection error: [Errno 111] Connection refused. Trying again in 32.0 seconds...
[2020-01-07 04:20:33,998: ERROR/MainProcess] beat: Connection error: [Errno 111] Connection refused. Trying again in 32.0 seconds...
[2020-01-07 04:21:06,052: ERROR/MainProcess] beat: Connection error: [Errno 111] Connection refused. Trying again in 32.0 seconds...
[2020-01-07 04:21:38,092: ERROR/MainProcess] beat: Connection error: [Errno 111] Connection refused. Trying again in 32.0 seconds...
[2020-01-07 04:22:10,141: ERROR/MainProcess] beat: Connection error: [Errno 111] Connection refused. Trying again in 32.0 seconds...
[2020-01-07 04:22:42,190: ERROR/MainProcess] beat: Connection error: [Errno 111] Connection refused. Trying again in 32.0 seconds...
[2020-01-07 04:23:14,226: ERROR/MainProcess] beat: Connection error: [Errno 111] Connection refused. Trying again in 32.0 seconds...
[2020-01-07 04:23:46,274: ERROR/MainProcess] beat: Connection error: [Errno 111] Connection refused. Trying again in 32.0 seconds...
[2020-01-07 04:24:18,324: ERROR/MainProcess] beat: Connection error: [Errno 111] Connection refused. Trying again in 32.0 seconds...
[2020-01-07 04:24:50,372: ERROR/MainProcess] beat: Connection error: [Errno 111] Connection refused. Trying again in 32.0 seconds...
[2020-01-07 04:25:22,420: ERROR/MainProcess] beat: Connection error: [Errno 111] Connection refused. Trying again in 32.0 seconds...
[2020-01-07 04:25:54,466: ERROR/MainProcess] beat: Connection error: [Errno 111] Connection refused. Trying again in 32.0 seconds...
[2020-01-07 04:26:26,515: ERROR/MainProcess] beat: Connection error: [Errno 111] Connection refused. Trying again in 32.0 seconds...
[2020-01-07 04:26:58,565: ERROR/MainProcess] beat: Connection error: [Errno 111] Connection refused. Trying again in 32.0 seconds...
[2020-01-07 04:27:30,614: ERROR/MainProcess] beat: Connection error: [Errno 111] Connection refused. Trying again in 32.0 seconds...
[2020-01-07 04:28:02,658: ERROR/MainProcess] beat: Connection error: [Errno 111] Connection refused. Trying again in 32.0 seconds...
[2020-01-07 04:28:34,705: ERROR/MainProcess] beat: Connection error: [Errno 111] Connection refused. Trying again in 32.0 seconds...
[2020-01-07 04:29:06,754: ERROR/MainProcess] beat: Connection error: [Errno 111] Connection refused. Trying again in 32.0 seconds...
[2020-01-07 04:29:38,799: ERROR/MainProcess] beat: Connection error: [Errno 111] Connection refused. Trying again in 32.0 seconds...
[2020-01-07 04:30:10,846: ERROR/MainProcess] beat: Connection error: [Errno 111] Connection refused. Trying again in 32.0 seconds...
[2020-01-07 04:30:42,894: ERROR/MainProcess] beat: Connection error: [Errno 111] Connection refused. Trying again in 32.0 seconds...
[2020-01-07 04:31:14,942: ERROR/MainProcess] beat: Connection error: [Errno 111] Connection refused. Trying again in 32.0 seconds...
[2020-01-07 04:31:46,988: ERROR/MainProcess] beat: Connection error: [Errno 111] Connection refused. Trying again in 32.0 seconds...
[2020-01-07 04:32:19,035: ERROR/MainProcess] beat: Connection error: [Errno 111] Connection refused. Trying again in 32.0 seconds...
[2020-01-07 04:32:51,081: ERROR/MainProcess] beat: Connection error: [Errno 111] Connection refused. Trying again in 32.0 seconds...
[2020-01-07 04:33:23,129: ERROR/MainProcess] beat: Connection error: [Errno 111] Connection refused. Trying again in 32.0 seconds...
[2020-01-07 04:33:55,175: ERROR/MainProcess] beat: Connection error: [Errno 111] Connection refused. Trying again in 32.0 seconds...
[2020-01-07 04:34:27,222: ERROR/MainProcess] beat: Connection error: [Errno 111] Connection refused. Trying again in 32.0 seconds...
[2020-01-07 04:34:59,267: ERROR/MainProcess] beat: Connection error: [Errno 111] Connection refused. Trying again in 32.0 seconds...
[2020-01-07 04:35:31,312: ERROR/MainProcess] beat: Connection error: [Errno 111] Connection refused. Trying again in 32.0 seconds...
[2020-01-07 04:36:03,363: ERROR/MainProcess] beat: Connection error: [Errno 111] Connection refused. Trying again in 32.0 seconds...
[2020-01-07 04:36:35,409: ERROR/MainProcess] beat: Connection error: [Errno 111] Connection refused. Trying again in 32.0 seconds...
[2020-01-07 04:37:07,455: ERROR/MainProcess] beat: Connection error: [Errno 111] Connection refused. Trying again in 32.0 seconds...
[2020-01-07 04:37:39,497: ERROR/MainProcess] beat: Connection error: [Errno 111] Connection refused. Trying again in 32.0 seconds...
[2020-01-07 04:38:11,550: ERROR/MainProcess] beat: Connection error: [Errno 111] Connection refused. Trying again in 32.0 seconds...
[2020-01-07 04:38:43,602: ERROR/MainProcess] beat: Connection error: [Errno 111] Connection refused. Trying again in 32.0 seconds...
[2020-01-07 04:39:15,647: ERROR/MainProcess] beat: Connection error: [Errno 111] Connection refused. Trying again in 32.0 seconds...
[2020-01-07 04:39:47,696: ERROR/MainProcess] beat: Connection error: [Errno 111] Connection refused. Trying again in 32.0 seconds...
[2020-01-07 04:40:19,749: ERROR/MainProcess] beat: Connection error: [Errno 111] Connection refused. Trying again in 32.0 seconds...
[2020-01-07 04:40:51,800: ERROR/MainProcess] beat: Connection error: [Errno 111] Connection refused. Trying again in 32.0 seconds...
[2020-01-07 04:41:23,849: ERROR/MainProcess] beat: Connection error: [Errno 111] Connection refused. Trying again in 32.0 seconds...
[2020-01-07 04:41:55,898: ERROR/MainProcess] beat: Connection error: [Errno 111] Connection refused. Trying again in 32.0 seconds...
[2020-01-07 04:42:27,947: ERROR/MainProcess] beat: Connection error: [Errno 111] Connection refused. Trying again in 32.0 seconds...
[2020-01-07 04:43:00,003: ERROR/MainProcess] beat: Connection error: [Errno 111] Connection refused. Trying again in 32.0 seconds...
[2020-01-07 04:43:32,050: ERROR/MainProcess] beat: Connection error: [Errno 111] Connection refused. Trying again in 32.0 seconds...
[2020-01-07 04:44:04,096: ERROR/MainProcess] beat: Connection error: [Errno 111] Connection refused. Trying again in 32.0 seconds...
[2020-01-07 04:44:36,141: ERROR/MainProcess] beat: Connection error: [Errno 111] Connection refused. Trying again in 32.0 seconds...
[2020-01-07 04:45:08,183: ERROR/MainProcess] beat: Connection error: [Errno 111] Connection refused. Trying again in 32.0 seconds...
[2020-01-07 04:45:40,223: ERROR/MainProcess] beat: Connection error: [Errno 111] Connection refused. Trying again in 32.0 seconds...
[2020-01-07 04:46:12,277: ERROR/MainProcess] beat: Connection error: [Errno 111] Connection refused. Trying again in 32.0 seconds...
[2020-01-07 04:46:44,326: ERROR/MainProcess] beat: Connection error: [Errno 111] Connection refused. Trying again in 32.0 seconds...
[2020-01-07 04:47:16,367: ERROR/MainProcess] beat: Connection error: [Errno 111] Connection refused. Trying again in 32.0 seconds...
[2020-01-07 04:47:48,412: ERROR/MainProcess] beat: Connection error: [Errno 111] Connection refused. Trying again in 32.0 seconds...
[2020-01-07 04:48:20,453: ERROR/MainProcess] beat: Connection error: [Errno 111] Connection refused. Trying again in 32.0 seconds...
[2020-01-07 04:48:52,502: ERROR/MainProcess] beat: Connection error: [Errno 111] Connection refused. Trying again in 32.0 seconds...
[2020-01-07 04:49:24,567: CRITICAL/MainProcess] beat raised exception <class 'kombu.exceptions.OperationalError'>: OperationalError('[Errno 111] Connection refused',)
Traceback (most recent call last):
  File "/usr/local/lib/python3.6/site-packages/kombu/utils/objects.py", line 42, in __get__
    return obj.__dict__[self.__name__]
KeyError: 'producer'

During handling of the above exception, another exception occurred:

Traceback (most recent call last):
  File "/usr/local/lib/python3.6/site-packages/amqp/transport.py", line 137, in _connect
    host, port, family, socket.SOCK_STREAM, SOL_TCP)
  File "/usr/local/lib/python3.6/socket.py", line 745, in getaddrinfo
    for res in _socket.getaddrinfo(host, port, family, type, proto, flags):
socket.gaierror: [Errno -9] Address family for hostname not supported

During handling of the above exception, another exception occurred:

Traceback (most recent call last):
  File "/usr/local/lib/python3.6/site-packages/kombu/connection.py", line 439, in _reraise_as_library_errors
    yield
  File "/usr/local/lib/python3.6/site-packages/kombu/connection.py", line 430, in ensure_connection
    callback, timeout=timeout)
  File "/usr/local/lib/python3.6/site-packages/kombu/utils/functional.py", line 344, in retry_over_time
    return fun(*args, **kwargs)
  File "/usr/local/lib/python3.6/site-packages/kombu/connection.py", line 283, in connect
    return self.connection
  File "/usr/local/lib/python3.6/site-packages/kombu/connection.py", line 839, in connection
    self._connection = self._establish_connection()
  File "/usr/local/lib/python3.6/site-packages/kombu/connection.py", line 794, in _establish_connection
    conn = self.transport.establish_connection()
  File "/usr/local/lib/python3.6/site-packages/kombu/transport/pyamqp.py", line 130, in establish_connection
    conn.connect()
  File "/usr/local/lib/python3.6/site-packages/amqp/connection.py", line 311, in connect
    self.transport.connect()
  File "/usr/local/lib/python3.6/site-packages/amqp/transport.py", line 77, in connect
    self._connect(self.host, self.port, self.connect_timeout)
  File "/usr/local/lib/python3.6/site-packages/amqp/transport.py", line 148, in _connect
    "failed to resolve broker hostname"))
  File "/usr/local/lib/python3.6/site-packages/amqp/transport.py", line 161, in _connect
    self.sock.connect(sa)
ConnectionRefusedError: [Errno 111] Connection refused

During handling of the above exception, another exception occurred:

Traceback (most recent call last):
  File "/usr/local/lib/python3.6/site-packages/celery/apps/beat.py", line 109, in start_scheduler
    service.start()
  File "/usr/local/lib/python3.6/site-packages/celery/beat.py", line 588, in start
    interval = self.scheduler.tick()
  File "/usr/local/lib/python3.6/site-packages/celery/beat.py", line 307, in tick
    self.apply_entry(entry, producer=self.producer)
  File "/usr/local/lib/python3.6/site-packages/kombu/utils/objects.py", line 44, in __get__
    value = obj.__dict__[self.__name__] = self.__get(obj)
  File "/usr/local/lib/python3.6/site-packages/celery/beat.py", line 441, in producer
    return self.Producer(self._ensure_connected(), auto_declare=False)
  File "/usr/local/lib/python3.6/site-packages/celery/beat.py", line 425, in _ensure_connected
    _error_handler, self.app.conf.broker_connection_max_retries
  File "/usr/local/lib/python3.6/site-packages/kombu/connection.py", line 430, in ensure_connection
    callback, timeout=timeout)
  File "/usr/local/lib/python3.6/contextlib.py", line 99, in __exit__
    self.gen.throw(type, value, traceback)
  File "/usr/local/lib/python3.6/site-packages/kombu/connection.py", line 444, in _reraise_as_library_errors
    sys.exc_info()[2])
  File "/usr/local/lib/python3.6/site-packages/vine/five.py", line 194, in reraise
    raise value.with_traceback(tb)
  File "/usr/local/lib/python3.6/site-packages/kombu/connection.py", line 439, in _reraise_as_library_errors
    yield
  File "/usr/local/lib/python3.6/site-packages/kombu/connection.py", line 430, in ensure_connection
    callback, timeout=timeout)
  File "/usr/local/lib/python3.6/site-packages/kombu/utils/functional.py", line 344, in retry_over_time
    return fun(*args, **kwargs)
  File "/usr/local/lib/python3.6/site-packages/kombu/connection.py", line 283, in connect
    return self.connection
  File "/usr/local/lib/python3.6/site-packages/kombu/connection.py", line 839, in connection
    self._connection = self._establish_connection()
  File "/usr/local/lib/python3.6/site-packages/kombu/connection.py", line 794, in _establish_connection
    conn = self.transport.establish_connection()
  File "/usr/local/lib/python3.6/site-packages/kombu/transport/pyamqp.py", line 130, in establish_connection
    conn.connect()
  File "/usr/local/lib/python3.6/site-packages/amqp/connection.py", line 311, in connect
    self.transport.connect()
  File "/usr/local/lib/python3.6/site-packages/amqp/transport.py", line 77, in connect
    self._connect(self.host, self.port, self.connect_timeout)
  File "/usr/local/lib/python3.6/site-packages/amqp/transport.py", line 148, in _connect
    "failed to resolve broker hostname"))
  File "/usr/local/lib/python3.6/site-packages/amqp/transport.py", line 161, in _connect
    self.sock.connect(sa)
kombu.exceptions.OperationalError: [Errno 111] Connection refused
[2020-01-07 04:49:24,617: WARNING/MainProcess] Traceback (most recent call last):
[2020-01-07 04:49:24,617: WARNING/MainProcess] File "/usr/local/lib/python3.6/site-packages/kombu/utils/objects.py", line 42, in __get__
[2020-01-07 04:49:24,619: WARNING/MainProcess] return obj.__dict__[self.__name__]
[2020-01-07 04:49:24,619: WARNING/MainProcess] KeyError
[2020-01-07 04:49:24,620: WARNING/MainProcess] :
[2020-01-07 04:49:24,620: WARNING/MainProcess] 'producer'
[2020-01-07 04:49:24,620: WARNING/MainProcess] During handling of the above exception, another exception occurred:
[2020-01-07 04:49:24,620: WARNING/MainProcess] Traceback (most recent call last):
[2020-01-07 04:49:24,620: WARNING/MainProcess] File "/usr/local/lib/python3.6/site-packages/amqp/transport.py", line 137, in _connect
[2020-01-07 04:49:24,620: WARNING/MainProcess] host, port, family, socket.SOCK_STREAM, SOL_TCP)
[2020-01-07 04:49:24,620: WARNING/MainProcess] File "/usr/local/lib/python3.6/socket.py", line 745, in getaddrinfo
[2020-01-07 04:49:24,622: WARNING/MainProcess] for res in _socket.getaddrinfo(host, port, family, type, proto, flags):
[2020-01-07 04:49:24,622: WARNING/MainProcess] socket
[2020-01-07 04:49:24,622: WARNING/MainProcess] .
[2020-01-07 04:49:24,622: WARNING/MainProcess] gaierror
[2020-01-07 04:49:24,622: WARNING/MainProcess] :
[2020-01-07 04:49:24,622: WARNING/MainProcess] [Errno -9] Address family for hostname not supported
[2020-01-07 04:49:24,623: WARNING/MainProcess] During handling of the above exception, another exception occurred:
[2020-01-07 04:49:24,623: WARNING/MainProcess] Traceback (most recent call last):
[2020-01-07 04:49:24,623: WARNING/MainProcess] File "/usr/local/lib/python3.6/site-packages/kombu/connection.py", line 439, in _reraise_as_library_errors
[2020-01-07 04:49:24,623: WARNING/MainProcess] yield
[2020-01-07 04:49:24,623: WARNING/MainProcess] File "/usr/local/lib/python3.6/site-packages/kombu/connection.py", line 430, in ensure_connection
[2020-01-07 04:49:24,623: WARNING/MainProcess] callback, timeout=timeout)
[2020-01-07 04:49:24,623: WARNING/MainProcess] File "/usr/local/lib/python3.6/site-packages/kombu/utils/functional.py", line 344, in retry_over_time
[2020-01-07 04:49:24,624: WARNING/MainProcess] return fun(*args, **kwargs)
[2020-01-07 04:49:24,624: WARNING/MainProcess] File "/usr/local/lib/python3.6/site-packages/kombu/connection.py", line 283, in connect
[2020-01-07 04:49:24,624: WARNING/MainProcess] return self.connection
[2020-01-07 04:49:24,624: WARNING/MainProcess] File "/usr/local/lib/python3.6/site-packages/kombu/connection.py", line 839, in connection
[2020-01-07 04:49:24,624: WARNING/MainProcess] self._connection = self._establish_connection()
[2020-01-07 04:49:24,624: WARNING/MainProcess] File "/usr/local/lib/python3.6/site-packages/kombu/connection.py", line 794, in _establish_connection
[2020-01-07 04:49:24,625: WARNING/MainProcess] conn = self.transport.establish_connection()
[2020-01-07 04:49:24,625: WARNING/MainProcess] File "/usr/local/lib/python3.6/site-packages/kombu/transport/pyamqp.py", line 130, in establish_connection
[2020-01-07 04:49:24,625: WARNING/MainProcess] conn.connect()
[2020-01-07 04:49:24,625: WARNING/MainProcess] File "/usr/local/lib/python3.6/site-packages/amqp/connection.py", line 311, in connect
[2020-01-07 04:49:24,625: WARNING/MainProcess] self.transport.connect()
[2020-01-07 04:49:24,625: WARNING/MainProcess] File "/usr/local/lib/python3.6/site-packages/amqp/transport.py", line 77, in connect
[2020-01-07 04:49:24,626: WARNING/MainProcess] self._connect(self.host, self.port, self.connect_timeout)
[2020-01-07 04:49:24,626: WARNING/MainProcess] File "/usr/local/lib/python3.6/site-packages/amqp/transport.py", line 148, in _connect
[2020-01-07 04:49:24,626: WARNING/MainProcess] "failed to resolve broker hostname"))
[2020-01-07 04:49:24,626: WARNING/MainProcess] File "/usr/local/lib/python3.6/site-packages/amqp/transport.py", line 161, in _connect
[2020-01-07 04:49:24,626: WARNING/MainProcess] self.sock.connect(sa)
[2020-01-07 04:49:24,626: WARNING/MainProcess] ConnectionRefusedError
[2020-01-07 04:49:24,626: WARNING/MainProcess] :
[2020-01-07 04:49:24,626: WARNING/MainProcess] [Errno 111] Connection refused
[2020-01-07 04:49:24,626: WARNING/MainProcess] During handling of the above exception, another exception occurred:
[2020-01-07 04:49:24,627: WARNING/MainProcess] Traceback (most recent call last):
[2020-01-07 04:49:24,627: WARNING/MainProcess] File "/usr/local/bin/celery", line 8, in <module>
[2020-01-07 04:49:24,627: WARNING/MainProcess] sys.exit(main())
[2020-01-07 04:49:24,628: WARNING/MainProcess] File "/usr/local/lib/python3.6/site-packages/celery/__main__.py", line 16, in main
[2020-01-07 04:49:24,628: WARNING/MainProcess] _main()
[2020-01-07 04:49:24,628: WARNING/MainProcess] File "/usr/local/lib/python3.6/site-packages/celery/bin/celery.py", line 322, in main
[2020-01-07 04:49:24,631: WARNING/MainProcess] cmd.execute_from_commandline(argv)
[2020-01-07 04:49:24,631: WARNING/MainProcess] File "/usr/local/lib/python3.6/site-packages/celery/bin/celery.py", line 496, in execute_from_commandline
[2020-01-07 04:49:24,632: WARNING/MainProcess] super(CeleryCommand, self).execute_from_commandline(argv)))
[2020-01-07 04:49:24,632: WARNING/MainProcess] File "/usr/local/lib/python3.6/site-packages/celery/bin/base.py", line 275, in execute_from_commandline
[2020-01-07 04:49:24,633: WARNING/MainProcess] return self.handle_argv(self.prog_name, argv[1:])
[2020-01-07 04:49:24,633: WARNING/MainProcess] File "/usr/local/lib/python3.6/site-packages/celery/bin/celery.py", line 488, in handle_argv
[2020-01-07 04:49:24,633: WARNING/MainProcess] return self.execute(command, argv)
[2020-01-07 04:49:24,633: WARNING/MainProcess] File "/usr/local/lib/python3.6/site-packages/celery/bin/celery.py", line 420, in execute
[2020-01-07 04:49:24,633: WARNING/MainProcess] ).run_from_argv(self.prog_name, argv[1:], command=argv[0])
[2020-01-07 04:49:24,633: WARNING/MainProcess] File "/usr/local/lib/python3.6/site-packages/celery/bin/base.py", line 279, in run_from_argv
[2020-01-07 04:49:24,634: WARNING/MainProcess] sys.argv if argv is None else argv, command)
[2020-01-07 04:49:24,634: WARNING/MainProcess] File "/usr/local/lib/python3.6/site-packages/celery/bin/base.py", line 363, in handle_argv
[2020-01-07 04:49:24,634: WARNING/MainProcess] return self(*args, **options)
[2020-01-07 04:49:24,634: WARNING/MainProcess] File "/usr/local/lib/python3.6/site-packages/celery/bin/base.py", line 238, in __call__
[2020-01-07 04:49:24,634: WARNING/MainProcess] ret = self.run(*args, **kwargs)
[2020-01-07 04:49:24,634: WARNING/MainProcess] File "/usr/local/lib/python3.6/site-packages/celery/bin/beat.py", line 109, in run
[2020-01-07 04:49:24,635: WARNING/MainProcess] return beat().run()
[2020-01-07 04:49:24,635: WARNING/MainProcess] File "/usr/local/lib/python3.6/site-packages/celery/apps/beat.py", line 81, in run
[2020-01-07 04:49:24,635: WARNING/MainProcess] self.start_scheduler()
[2020-01-07 04:49:24,635: WARNING/MainProcess] File "/usr/local/lib/python3.6/site-packages/celery/apps/beat.py", line 109, in start_scheduler
[2020-01-07 04:49:24,635: WARNING/MainProcess] service.start()
[2020-01-07 04:49:24,636: WARNING/MainProcess] File "/usr/local/lib/python3.6/site-packages/celery/beat.py", line 588, in start
[2020-01-07 04:49:24,636: WARNING/MainProcess] interval = self.scheduler.tick()
[2020-01-07 04:49:24,636: WARNING/MainProcess] File "/usr/local/lib/python3.6/site-packages/celery/beat.py", line 307, in tick
[2020-01-07 04:49:24,636: WARNING/MainProcess] self.apply_entry(entry, producer=self.producer)
[2020-01-07 04:49:24,636: WARNING/MainProcess] File "/usr/local/lib/python3.6/site-packages/kombu/utils/objects.py", line 44, in __get__
[2020-01-07 04:49:24,636: WARNING/MainProcess] value = obj.__dict__[self.__name__] = self.__get(obj)
[2020-01-07 04:49:24,636: WARNING/MainProcess] File "/usr/local/lib/python3.6/site-packages/celery/beat.py", line 441, in producer
[2020-01-07 04:49:24,637: WARNING/MainProcess] return self.Producer(self._ensure_connected(), auto_declare=False)
[2020-01-07 04:49:24,637: WARNING/MainProcess] File "/usr/local/lib/python3.6/site-packages/celery/beat.py", line 425, in _ensure_connected
[2020-01-07 04:49:24,637: WARNING/MainProcess] _error_handler, self.app.conf.broker_connection_max_retries
[2020-01-07 04:49:24,637: WARNING/MainProcess] File "/usr/local/lib/python3.6/site-packages/kombu/connection.py", line 430, in ensure_connection
[2020-01-07 04:49:24,637: WARNING/MainProcess] callback, timeout=timeout)
[2020-01-07 04:49:24,637: WARNING/MainProcess] File "/usr/local/lib/python3.6/contextlib.py", line 99, in __exit__
[2020-01-07 04:49:24,638: WARNING/MainProcess] self.gen.throw(type, value, traceback)
[2020-01-07 04:49:24,638: WARNING/MainProcess] File "/usr/local/lib/python3.6/site-packages/kombu/connection.py", line 444, in _reraise_as_library_errors
[2020-01-07 04:49:24,638: WARNING/MainProcess] sys.exc_info()[2])
[2020-01-07 04:49:24,638: WARNING/MainProcess] File "/usr/local/lib/python3.6/site-packages/vine/five.py", line 194, in reraise
[2020-01-07 04:49:24,638: WARNING/MainProcess] raise value.with_traceback(tb)
[2020-01-07 04:49:24,638: WARNING/MainProcess] File "/usr/local/lib/python3.6/site-packages/kombu/connection.py", line 439, in _reraise_as_library_errors
[2020-01-07 04:49:24,638: WARNING/MainProcess] yield
[2020-01-07 04:49:24,639: WARNING/MainProcess] File "/usr/local/lib/python3.6/site-packages/kombu/connection.py", line 430, in ensure_connection
[2020-01-07 04:49:24,639: WARNING/MainProcess] callback, timeout=timeout)
[2020-01-07 04:49:24,639: WARNING/MainProcess] File "/usr/local/lib/python3.6/site-packages/kombu/utils/functional.py", line 344, in retry_over_time
[2020-01-07 04:49:24,639: WARNING/MainProcess] return fun(*args, **kwargs)
[2020-01-07 04:49:24,639: WARNING/MainProcess] File "/usr/local/lib/python3.6/site-packages/kombu/connection.py", line 283, in connect
[2020-01-07 04:49:24,640: WARNING/MainProcess] return self.connection
[2020-01-07 04:49:24,640: WARNING/MainProcess] File "/usr/local/lib/python3.6/site-packages/kombu/connection.py", line 839, in connection
[2020-01-07 04:49:24,640: WARNING/MainProcess] self._connection = self._establish_connection()
[2020-01-07 04:49:24,640: WARNING/MainProcess] File "/usr/local/lib/python3.6/site-packages/kombu/connection.py", line 794, in _establish_connection
[2020-01-07 04:49:24,640: WARNING/MainProcess] conn = self.transport.establish_connection()
[2020-01-07 04:49:24,641: WARNING/MainProcess] File "/usr/local/lib/python3.6/site-packages/kombu/transport/pyamqp.py", line 130, in establish_connection
[2020-01-07 04:49:24,641: WARNING/MainProcess] conn.connect()
[2020-01-07 04:49:24,641: WARNING/MainProcess] File "/usr/local/lib/python3.6/site-packages/amqp/connection.py", line 311, in connect
[2020-01-07 04:49:24,641: WARNING/MainProcess] self.transport.connect()
[2020-01-07 04:49:24,641: WARNING/MainProcess] File "/usr/local/lib/python3.6/site-packages/amqp/transport.py", line 77, in connect
[2020-01-07 04:49:24,641: WARNING/MainProcess] self._connect(self.host, self.port, self.connect_timeout)
[2020-01-07 04:49:24,641: WARNING/MainProcess] File "/usr/local/lib/python3.6/site-packages/amqp/transport.py", line 148, in _connect
[2020-01-07 04:49:24,641: WARNING/MainProcess] "failed to resolve broker hostname"))
[2020-01-07 04:49:24,642: WARNING/MainProcess] File "/usr/local/lib/python3.6/site-packages/amqp/transport.py", line 161, in _connect
[2020-01-07 04:49:24,642: WARNING/MainProcess] self.sock.connect(sa)
[2020-01-07 04:49:24,642: WARNING/MainProcess] kombu.exceptions
[2020-01-07 04:49:24,642: WARNING/MainProcess] .
[2020-01-07 04:49:24,642: WARNING/MainProcess] OperationalError
[2020-01-07 04:49:24,642: WARNING/MainProcess] :
[2020-01-07 04:49:24,642: WARNING/MainProcess] [Errno 111] Connection refused
[2020-01-07 06:38:04,885: INFO/MainProcess] beat: Starting...
[2020-01-07 06:38:49,267: INFO/MainProcess] beat: Starting...
